Workbook

Sheet Summary
A1: EU Cyber Resilience Act — Compliance Assessment
A2: Regulation (EU) 2024/2847
A4: Product Description | B4: SecureFlow is a secure digital platform designed to streamline the management, analysis, and protection of sensitive information within organizations. It enables teams to securely collect, process, and share data through controlled workflows while maintaining strict access control and traceability. The platform integrates advanced security mechanisms such as end-to-end encryption, role-based access management, and automated audit logging to ensure compliance with modern cybersecurity and data protection standards. By centralizing processes and enforcing secure data handling practices, SecureFlow helps organizations reduce operational risks, improve collaboration, and maintain full visibility over critical information flows.
A5: CRA Classification | B5: CLASS I
A6: Annex III Categories | B6: Identity management systems and privileged access management software/hardware (including authentication readers, biometric readers), Network management systems, SIEM systems (security information and event management)
A7: Actor Role | B7: manufacturer
A8: Classification Confidence | B8: high
A9: Classification Reasoning | B9: The product description highlights 'strict access control' and 'role-based access management', directly aligning with Identity and Access Management. 'Streamline the management, analysis, and protection of sensitive information' and 'visibility over critical information flows' point towards Network Management and SIEM capabilities, which deal with managing and monitoring network activities and security events.
A10: Conformity Assessment Route | B10: Art. 32(2): Self-assessment IF harmonised standards / common specs / EU cybersecurity certification (assurance level 'substantial') are applied. Otherwise: third-party assessment per Annex VIII (EU-type examination) or Art. 32(2)(b) conformity based on full quality assurance.
A12: Total Obligations | B12: 139
A13: Obligations with Verifications | B13: 0
A14: Obligations with Evidence Suggestions | B14: 114
A15: Obligations with Deadlines | B15: 16
A16: Articles Covered | B16: 19
A19: Status Legend
A20: Compliant | B20: All verification actions verified
A21: Not Compliant | B21: Obligation not met — action required
A22: Partially Compliant | B22: Some verifications verified
A23: Not Applicable | B23: Obligation does not apply to this product
A26: How to Use
A27: 1. Go to the 'Verification Actions' sheet
A28: 2. For each verification, set Status to 'Verified' or 'Not Verified'
A29: 3. The 'Obligations' sheet Status column auto-updates based on verification statuses
A30: 4. When ALL verifications for an obligation are 'Verified', the obligation becomes 'Compliant'
A31: 5. Override the auto-status in the Obligations sheet if needed (e.g. 'Not Applicable')
A32: 6. Use the Evidence column to reference your documentation
A33: 7. Filter by Article or Status to focus on specific areas

Sheet Obligations
A1: # | B1: Obligation ID | C1: Article | D1: Article Title | E1: Paragraph | F1: Obligation | G1: Trigger | H1: Deadline | I1: Status | J1: Evidence | K1: Notes
A2: 1 | B2: AnnI_PartII_par3_17 | C2: Annex I | E2: Annex I, Part II, point 3 | F2: apply effective and regular tests and reviews of the security of the product with digital elements | I2: =IF(COUNTIF('Verification Actions'!B2:B343,"* "&B2&" *")=0,"",IF(COUNTIFS('Verification Actions'!B2:B343,"* "&B2&" *",'Verification Actions'!E2:E343,"Verified")=COUNTIF('Verification Actions'!B2:B343,"* "&B2&" *"),"Compliant",IF(COUNTIFS('Verification Actions'!B2:B343,"* "&B2&" *",'Verification Actions'!E2:E343,"Verified")>0,"Partially Compliant","Not Compliant")))
A3: 2 | B3: AnnI_PartII_par4_18 | C3: Annex I | E3: Annex I, Part II, point 4 | F3: share and publicly disclose information about fixed vulnerabilities, including a description of the vulnerabilities, information allowing users to identify the product with digital elements affected, the impacts of the vulnerabilities, their severity and clear and accessible information helping users to remediate the vulnerabilities; in duly justified cases, where manufacturers consider the security risks of publication to outweigh the security benefits, they may delay making public information regarding a fixed vulnerability until after users have been given the possibility to apply the relevant patch | G3: Once a security update has been made available | I3: =IF(COUNTIF('Verification Actions'!B2:B343,"* "&B3&" *")=0,"",IF(COUNTIFS('Verification Actions'!B2:B343,"* "&B3&" *",'Verification Actions'!E2:E343,"Verified")=COUNTIF('Verification Actions'!B2:B343,"* "&B3&" *"),"Compliant",IF(COUNTIFS('Verification Actions'!B2:B343,"* "&B3&" *",'Verification Actions'!E2:E343,"Verified")>0,"Partially Compliant","Not Compliant")))
A4: 3 | B4: AnnI_PartII_par6_20 | C4: Annex I | E4: Annex I, Part II, point 6 | F4: take measures to facilitate the sharing of information about potential vulnerabilities in their product with digital elements as well as in third-party components contained in that product, including by providing a contact address for the reporting of the vulnerabilities discovered in the product with digital elements | I4: =IF(COUNTIF('Verification Actions'!B2:B343,"* "&B4&" *")=0,"",IF(COUNTIFS('Verification Actions'!B2:B343,"* "&B4&" *",'Verification Actions'!E2:E343,"Verified")=COUNTIF('Verification Actions'!B2:B343,"* "&B4&" *"),"Compliant",IF(COUNTIFS('Verification Actions'!B2:B343,"* "&B4&" *",'Verification Actions'!E2:E343,"Verified")>0,"Partially Compliant","Not Compliant")))
A5: 4 | B5: AnnI_PartII_par7_21 | C5: Annex I | E5: Annex I, Part II, point 7 | F5: provide for mechanisms to securely distribute updates for products with digital elements to ensure that vulnerabilities are fixed or mitigated in a timely manner and, where applicable for security updates, in an automatic manner | H5: in a timely manner | I5: =IF(COUNTIF('Verification Actions'!B2:B343,"* "&B5&" *")=0,"",IF(COUNTIFS('Verification Actions'!B2:B343,"* "&B5&" *",'Verification Actions'!E2:E343,"Verified")=COUNTIF('Verification Actions'!B2:B343,"* "&B5&" *"),"Compliant",IF(COUNTIFS('Verification Actions'!B2:B343,"* "&B5&" *",'Verification Actions'!E2:E343,"Verified")>0,"Partially Compliant","Not Compliant")))
A6: 5 | B6: AnnI_par1_1 | C6: Annex I | E6: Annex I, point 1 | F6: be designed, developed and produced in such a way that they ensure an appropriate level of cybersecurity based on the risks | I6: =IF(COUNTIF('Verification Actions'!B2:B343,"* "&B6&" *")=0,"",IF(COUNTIFS('Verification Actions'!B2:B343,"* "&B6&" *",'Verification Actions'!E2:E343,"Verified")=COUNTIF('Verification Actions'!B2:B343,"* "&B6&" *"),"Compliant",IF(COUNTIFS('Verification Actions'!B2:B343,"* "&B6&" *",'Verification Actions'!E2:E343,"Verified")>0,"Partially Compliant","Not Compliant")))
A7: 6 | B7: AnnI_par2_10 | C7: Annex I | E7: Annex I, point 2(i) | F7: minimise the negative impact by the products themselves or connected devices on the availability of services provided by other devices or networks | G7: On the basis of the cybersecurity risk assessment referred to in Article 13(2) and where applicable | I7: =IF(COUNTIF('Verification Actions'!B2:B343,"* "&B7&" *")=0,"",IF(COUNTIFS('Verification Actions'!B2:B343,"* "&B7&" *",'Verification Actions'!E2:E343,"Verified")=COUNTIF('Verification Actions'!B2:B343,"* "&B7&" *"),"Compliant",IF(COUNTIFS('Verification Actions'!B2:B343,"* "&B7&" *",'Verification Actions'!E2:E343,"Verified")>0,"Partially Compliant","Not Compliant")))
A8: 7 | B8: AnnI_par2_11 | C8: Annex I | E8: Annex I, point 2(j) | F8: be designed, developed and produced to limit attack surfaces, including external interfaces | G8: On the basis of the cybersecurity risk assessment referred to in Article 13(2) and where applicable | I8: =IF(COUNTIF('Verification Actions'!B2:B343,"* "&B8&" *")=0,"",IF(COUNTIFS('Verification Actions'!B2:B343,"* "&B8&" *",'Verification Actions'!E2:E343,"Verified")=COUNTIF('Verification Actions'!B2:B343,"* "&B8&" *"),"Compliant",IF(COUNTIFS('Verification Actions'!B2:B343,"* "&B8&" *",'Verification Actions'!E2:E343,"Verified")>0,"Partially Compliant","Not Compliant")))
A9: 8 | B9: AnnI_par2_12 | C9: Annex I | E9: Annex I, point 2(k) | F9: be designed, developed and produced to reduce the impact of an incident using appropriate exploitation mitigation mechanisms and techniques | G9: On the basis of the cybersecurity risk assessment referred to in Article 13(2) and where applicable | I9: =IF(COUNTIF('Verification Actions'!B2:B343,"* "&B9&" *")=0,"",IF(COUNTIFS('Verification Actions'!B2:B343,"* "&B9&" *",'Verification Actions'!E2:E343,"Verified")=COUNTIF('Verification Actions'!B2:B343,"* "&B9&" *"),"Compliant",IF(COUNTIFS('Verification Actions'!B2:B343,"* "&B9&" *",'Verification Actions'!E2:E343,"Verified")>0,"Partially Compliant","Not Compliant")))
A10: 9 | B10: AnnI_par2_13 | C10: Annex I | E10: Annex I, point 2(l) | F10: provide security related information by recording and monitoring relevant internal activity, including the access to or modification of data, services or functions, with an opt-out mechanism for the user | G10: On the basis of the cybersecurity risk assessment referred to in Article 13(2) and where applicable | I10: =IF(COUNTIF('Verification Actions'!B2:B343,"* "&B10&" *")=0,"",IF(COUNTIFS('Verification Actions'!B2:B343,"* "&B10&" *",'Verification Actions'!E2:E343,"Verified")=COUNTIF('Verification Actions'!B2:B343,"* "&B10&" *"),"Compliant",IF(COUNTIFS('Verification Actions'!B2:B343,"* "&B10&" *",'Verification Actions'!E2:E343,"Verified")>0,"Partially Compliant","Not Compliant")))
A11: 10 | B11: AnnI_par2_14 | C11: Annex I | E11: Annex I, point 2(m) | F11: provide the possibility for users to securely and easily remove on a permanent basis all data and settings and, where such data can be transferred to other products or systems, ensure that this is done in a secure manner | G11: On the basis of the cybersecurity risk assessment referred to in Article 13(2) and where applicable | I11: =IF(COUNTIF('Verification Actions'!B2:B343,"* "&B11&" *")=0,"",IF(COUNTIFS('Verification Actions'!B2:B343,"* "&B11&" *",'Verification Actions'!E2:E343,"Verified")=COUNTIF('Verification Actions'!B2:B343,"* "&B11&" *"),"Compliant",IF(COUNTIFS('Verification Actions'!B2:B343,"* "&B11&" *",'Verification Actions'!E2:E343,"Verified")>0,"Partially Compliant","Not Compliant")))
A12: 11 | B12: AnnI_par2_2 | C12: Annex I | E12: Annex I, point 2(a) | F12: be made available on the market without known exploitable vulnerabilities | G12: On the basis of the cybersecurity risk assessment referred to in Article 13(2) and where applicable | I12: =IF(COUNTIF('Verification Actions'!B2:B343,"* "&B12&" *")=0,"",IF(COUNTIFS('Verification Actions'!B2:B343,"* "&B12&" *",'Verification Actions'!E2:E343,"Verified")=COUNTIF('Verification Actions'!B2:B343,"* "&B12&" *"),"Compliant",IF(COUNTIFS('Verification Actions'!B2:B343,"* "&B12&" *",'Verification Actions'!E2:E343,"Verified")>0,"Partially Compliant","Not Compliant")))
A13: 12 | B13: AnnI_par2_3 | C13: Annex I | E13: Annex I, point 2(b) | F13: be made available on the market with a secure by default configuration, unless otherwise agreed between manufacturer and business user in relation to a tailor-made product with digital elements, including the possibility to reset the product to its original state | G13: On the basis of the cybersecurity risk assessment referred to in Article 13(2) and where applicable | I13: =IF(COUNTIF('Verification Actions'!B2:B343,"* "&B13&" *")=0,"",IF(COUNTIFS('Verification Actions'!B2:B343,"* "&B13&" *",'Verification Actions'!E2:E343,"Verified")=COUNTIF('Verification Actions'!B2:B343,"* "&B13&" *"),"Compliant",IF(COUNTIFS('Verification Actions'!B2:B343,"* "&B13&" *",'Verification Actions'!E2:E343,"Verified")>0,"Partially Compliant","Not Compliant")))
A14: 13 | B14: AnnI_par2_4 | C14: Annex I | E14: Annex I, point 2(c) | F14: ensure that vulnerabilities can be addressed through security updates, including, where applicable, through automatic security updates that are installed within an appropriate timeframe enabled as a default setting, with a clear and easy-to-use opt-out mechanism, through the notification of available updates to users, and the option to temporarily postpone them | G14: On the basis of the cybersecurity risk assessment referred to in Article 13(2) and where applicable | I14: =IF(COUNTIF('Verification Actions'!B2:B343,"* "&B14&" *")=0,"",IF(COUNTIFS('Verification Actions'!B2:B343,"* "&B14&" *",'Verification Actions'!E2:E343,"Verified")=COUNTIF('Verification Actions'!B2:B343,"* "&B14&" *"),"Compliant",IF(COUNTIFS('Verification Actions'!B2:B343,"* "&B14&" *",'Verification Actions'!E2:E343,"Verified")>0,"Partially Compliant","Not Compliant")))
A15: 14 | B15: AnnI_par2_5 | C15: Annex I | E15: Annex I, point 2(d) | F15: ensure protection from unauthorised access by appropriate control mechanisms, including but not limited to authentication, identity or access management systems, and report on possible unauthorised access | G15: On the basis of the cybersecurity risk assessment referred to in Article 13(2) and where applicable | I15: =IF(COUNTIF('Verification Actions'!B2:B343,"* "&B15&" *")=0,"",IF(COUNTIFS('Verification Actions'!B2:B343,"* "&B15&" *",'Verification Actions'!E2:E343,"Verified")=COUNTIF('Verification Actions'!B2:B343,"* "&B15&" *"),"Compliant",IF(COUNTIFS('Verification Actions'!B2:B343,"* "&B15&" *",'Verification Actions'!E2:E343,"Verified")>0,"Partially Compliant","Not Compliant")))
A16: 15 | B16: AnnI_par2_6 | C16: Annex I | E16: Annex I, point 2(e) | F16: protect the confidentiality of stored, transmitted or otherwise processed data, personal or other, such as by encrypting relevant data at rest or in transit by state of the art mechanisms, and by using other technical means | G16: On the basis of the cybersecurity risk assessment referred to in Article 13(2) and where applicable | I16: =IF(COUNTIF('Verification Actions'!B2:B343,"* "&B16&" *")=0,"",IF(COUNTIFS('Verification Actions'!B2:B343,"* "&B16&" *",'Verification Actions'!E2:E343,"Verified")=COUNTIF('Verification Actions'!B2:B343,"* "&B16&" *"),"Compliant",IF(COUNTIFS('Verification Actions'!B2:B343,"* "&B16&" *",'Verification Actions'!E2:E343,"Verified")>0,"Partially Compliant","Not Compliant")))
A17: 16 | B17: AnnI_par2_7 | C17: Annex I | E17: Annex I, point 2(f) | F17: protect the integrity of stored, transmitted or otherwise processed data, personal or other, commands, programs and configuration against any manipulation or modification not authorised by the user, and report on corruptions | G17: On the basis of the cybersecurity risk assessment referred to in Article 13(2) and where applicable | I17: =IF(COUNTIF('Verification Actions'!B2:B343,"* "&B17&" *")=0,"",IF(COUNTIFS('Verification Actions'!B2:B343,"* "&B17&" *",'Verification Actions'!E2:E343,"Verified")=COUNTIF('Verification Actions'!B2:B343,"* "&B17&" *"),"Compliant",IF(COUNTIFS('Verification Actions'!B2:B343,"* "&B17&" *",'Verification Actions'!E2:E343,"Verified")>0,"Partially Compliant","Not Compliant")))
A18: 17 | B18: AnnI_par2_8 | C18: Annex I | E18: Annex I, point 2(g) | F18: process only data, personal or other, that are adequate, relevant and limited to what is necessary in relation to the intended purpose of the product with digital elements (data minimisation) | G18: On the basis of the cybersecurity risk assessment referred to in Article 13(2) and where applicable | I18: =IF(COUNTIF('Verification Actions'!B2:B343,"* "&B18&" *")=0,"",IF(COUNTIFS('Verification Actions'!B2:B343,"* "&B18&" *",'Verification Actions'!E2:E343,"Verified")=COUNTIF('Verification Actions'!B2:B343,"* "&B18&" *"),"Compliant",IF(COUNTIFS('Verification Actions'!B2:B343,"* "&B18&" *",'Verification Actions'!E2:E343,"Verified")>0,"Partially Compliant","Not Compliant")))
A19: 18 | B19: AnnI_par2_9 | C19: Annex I | E19: Annex I, point 2(h) | F19: protect the availability of essential and basic functions, also after an incident, including through resilience and mitigation measures against denial-of-service attacks | G19: On the basis of the cybersecurity risk assessment referred to in Article 13(2) and where applicable | I19: =IF(COUNTIF('Verification Actions'!B2:B343,"* "&B19&" *")=0,"",IF(COUNTIFS('Verification Actions'!B2:B343,"* "&B19&" *",'Verification Actions'!E2:E343,"Verified")=COUNTIF('Verification Actions'!B2:B343,"* "&B19&" *"),"Compliant",IF(COUNTIFS('Verification Actions'!B2:B343,"* "&B19&" *",'Verification Actions'!E2:E343,"Verified")>0,"Partially Compliant","Not Compliant")))
A20: 19 | B20: AnnI_PartII_par1_15 | C20: Annex I | E20: Annex I, Part II, point 1 | F20: identify and document vulnerabilities and components contained in products with digital elements, including by drawing up a software bill of materials in a commonly used and machine-readable format covering at the very least the top-level dependencies of the products | I20: =IF(COUNTIF('Verification Actions'!B2:B343,"* "&B20&" *")=0,"",IF(COUNTIFS('Verification Actions'!B2:B343,"* "&B20&" *",'Verification Actions'!E2:E343,"Verified")=COUNTIF('Verification Actions'!B2:B343,"* "&B20&" *"),"Compliant",IF(COUNTIFS('Verification Actions'!B2:B343,"* "&B20&" *",'Verification Actions'!E2:E343,"Verified")>0,"Partially Compliant","Not Compliant")))
A21: 20 | B21: AnnI_PartII_par2_16 | C21: Annex I | E21: Annex I, Part II, point 2 | F21: address and remediate vulnerabilities without delay, including by providing security updates; where technically feasible, new security updates shall be provided separately from functionality updates | G21: In relation to the risks posed to products with digital elements | H21: without delay | I21: =IF(COUNTIF('Verification Actions'!B2:B343,"* "&B21&" *")=0,"",IF(COUNTIFS('Verification Actions'!B2:B343,"* "&B21&" *",'Verification Actions'!E2:E343,"Verified")=COUNTIF('Verification Actions'!B2:B343,"* "&B21&" *"),"Compliant",IF(COUNTIFS('Verification Actions'!B2:B343,"* "&B21&" *",'Verification Actions'!E2:E343,"Verified")>0,"Partially Compliant","Not Compliant")))
A22: 21 | B22: AnnI_PartII_par5_19 | C22: Annex I | E22: Annex I, Part II, point 5 | F22: put in place and enforce a policy on coordinated vulnerability disclosure | I22: =IF(COUNTIF('Verification Actions'!B2:B343,"* "&B22&" *")=0,"",IF(COUNTIFS('Verification Actions'!B2:B343,"* "&B22&" *",'Verification Actions'!E2:E343,"Verified")=COUNTIF('Verification Actions'!B2:B343,"* "&B22&" *"),"Compliant",IF(COUNTIFS('Verification Actions'!B2:B343,"* "&B22&" *",'Verification Actions'!E2:E343,"Verified")>0,"Partially Compliant","Not Compliant")))
A23: 22 | B23: AnnI_PartII_par8_22 | C23: Annex I | E23: Annex I, Part II, point 8 | F23: ensure that, where security updates are available to address identified security issues, they are disseminated without delay and, unless otherwise agreed between a manufacturer and a business user in relation to a tailor-made product with digital elements, free of charge, accompanied by advisory messages providing users with the relevant information, including on potential action to be taken | G23: Where security updates are available to address identified security issues | H23: without delay | I23: =IF(COUNTIF('Verification Actions'!B2:B343,"* "&B23&" *")=0,"",IF(COUNTIFS('Verification Actions'!B2:B343,"* "&B23&" *",'Verification Actions'!E2:E343,"Verified")=COUNTIF('Verification Actions'!B2:B343,"* "&B23&" *"),"Compliant",IF(COUNTIFS('Verification Actions'!B2:B343,"* "&B23&" *",'Verification Actions'!E2:E343,"Verified")>0,"Partially Compliant","Not Compliant")))
A24: 23 | B24: AnnII_par1_1 | C24: Annex II | E24: Annex II, point 1 | F24: accompany the product with digital elements with the name, registered trade name or registered trademark, and the postal address, the email address or other digital contact as well as, where available, the website at which the manufacturer can be contacted | I24: =IF(COUNTIF('Verification Actions'!B2:B343,"* "&B24&" *")=0,"",IF(COUNTIFS('Verification Actions'!B2:B343,"* "&B24&" *",'Verification Actions'!E2:E343,"Verified")=COUNTIF('Verification Actions'!B2:B343,"* "&B24&" *"),"Compliant",IF(COUNTIFS('Verification Actions'!B2:B343,"* "&B24&" *",'Verification Actions'!E2:E343,"Verified")>0,"Partially Compliant","Not Compliant")))
A25: 24 | B25: AnnII_par2_2 | C25: Annex II | E25: Annex II, point 2 | F25: accompany the product with digital elements with the single point of contact where information about vulnerabilities of the product with digital elements can be reported and received, and where the manufacturer’s policy on coordinated vulnerability disclosure can be found | I25: =IF(COUNTIF('Verification Actions'!B2:B343,"* "&B25&" *")=0,"",IF(COUNTIFS('Verification Actions'!B2:B343,"* "&B25&" *",'Verification Actions'!E2:E343,"Verified")=COUNTIF('Verification Actions'!B2:B343,"* "&B25&" *"),"Compliant",IF(COUNTIFS('Verification Actions'!B2:B343,"* "&B25&" *",'Verification Actions'!E2:E343,"Verified")>0,"Partially Compliant","Not Compliant")))
A26: 25 | B26: AnnII_par3_3 | C26: Annex II | E26: Annex II, point 3 | F26: accompany the product with digital elements with name and type and any additional information enabling the unique identification of the product with digital elements | I26: =IF(COUNTIF('Verification Actions'!B2:B343,"* "&B26&" *")=0,"",IF(COUNTIFS('Verification Actions'!B2:B343,"* "&B26&" *",'Verification Actions'!E2:E343,"Verified")=COUNTIF('Verification Actions'!B2:B343,"* "&B26&" *"),"Compliant",IF(COUNTIFS('Verification Actions'!B2:B343,"* "&B26&" *",'Verification Actions'!E2:E343,"Verified")>0,"Partially Compliant","Not Compliant")))
A27: 26 | B27: AnnII_par4_4 | C27: Annex II | E27: Annex II, point 4 | F27: accompany the product with digital elements with the intended purpose, including the security environment provided by the manufacturer, as well as the product’s essential functionalities and information about the security properties | I27: =IF(COUNTIF('Verification Actions'!B2:B343,"* "&B27&" *")=0,"",IF(COUNTIFS('Verification Actions'!B2:B343,"* "&B27&" *",'Verification Actions'!E2:E343,"Verified")=COUNTIF('Verification Actions'!B2:B343,"* "&B27&" *"),"Compliant",IF(COUNTIFS('Verification Actions'!B2:B343,"* "&B27&" *",'Verification Actions'!E2:E343,"Verified")>0,"Partially Compliant","Not Compliant")))
A28: 27 | B28: AnnII_par5_5 | C28: Annex II | E28: Annex II, point 5 | F28: accompany the product with digital elements with any known or foreseeable circumstance, related to the use of the product with digital elements in accordance with its intended purpose or under conditions of reasonably foreseeable misuse, which may lead to significant cybersecurity risks | I28: =IF(COUNTIF('Verification Actions'!B2:B343,"* "&B28&" *")=0,"",IF(COUNTIFS('Verification Actions'!B2:B343,"* "&B28&" *",'Verification Actions'!E2:E343,"Verified")=COUNTIF('Verification Actions'!B2:B343,"* "&B28&" *"),"Compliant",IF(COUNTIFS('Verification Actions'!B2:B343,"* "&B28&" *",'Verification Actions'!E2:E343,"Verified")>0,"Partially Compliant","Not Compliant")))
A29: 28 | B29: AnnII_par6_6 | C29: Annex II | E29: Annex II, point 6 | F29: accompany the product with digital elements with the internet address at which the EU declaration of conformity can be accessed, where applicable | I29: =IF(COUNTIF('Verification Actions'!B2:B343,"* "&B29&" *")=0,"",IF(COUNTIFS('Verification Actions'!B2:B343,"* "&B29&" *",'Verification Actions'!E2:E343,"Verified")=COUNTIF('Verification Actions'!B2:B343,"* "&B29&" *"),"Compliant",IF(COUNTIFS('Verification Actions'!B2:B343,"* "&B29&" *",'Verification Actions'!E2:E343,"Verified")>0,"Partially Compliant","Not Compliant")))
A30: 29 | B30: AnnII_par7_7 | C30: Annex II | E30: Annex II, point 7 | F30: accompany the product with digital elements with the type of technical security support offered by the manufacturer and the end-date of the support period during which users can expect vulnerabilities to be handled and to receive security updates | I30: =IF(COUNTIF('Verification Actions'!B2:B343,"* "&B30&" *")=0,"",IF(COUNTIFS('Verification Actions'!B2:B343,"* "&B30&" *",'Verification Actions'!E2:E343,"Verified")=COUNTIF('Verification Actions'!B2:B343,"* "&B30&" *"),"Compliant",IF(COUNTIFS('Verification Actions'!B2:B343,"* "&B30&" *",'Verification Actions'!E2:E343,"Verified")>0,"Partially Compliant","Not Compliant")))
A31: 30 | B31: AnnII_par8_8 | C31: Annex II | E31: Annex II, point 8 | F31: accompany the product with digital elements with detailed instructions or an internet address referring to such detailed instructions and information on: the necessary measures during initial commissioning and throughout the lifetime of the product with digital elements to ensure its secure use; how changes to the product with digital elements can affect the security of data; how security-relevant updates can be installed; the secure decommissioning of the product with digital elements, including information on how user data can be securely removed; how the default setting enabling the automatic installation of security updates, as required by Part I, point (2)(c), of Annex I, can be turned off; where the product with digital elements is intended for integration into other products with digital elements, the information necessary for the integrator to comply with the essential cybersecurity requirements set out in Annex I and the documentation requirements set out in Annex VII | I31: =IF(COUNTIF('Verification Actions'!B2:B343,"* "&B31&" *")=0,"",IF(COUNTIFS('Verification Actions'!B2:B343,"* "&B31&" *",'Verification Actions'!E2:E343,"Verified")=COUNTIF('Verification Actions'!B2:B343,"* "&B31&" *"),"Compliant",IF(COUNTIFS('Verification Actions'!B2:B343,"* "&B31&" *",'Verification Actions'!E2:E343,"Verified")>0,"Partially Compliant","Not Compliant")))
A32: 31 | B32: AnnII_par9_9 | C32: Annex II | E32: Annex II, point 9 | F32: make available information on where the software bill of materials can be accessed, if the manufacturer decides to make it available to the user | I32: =IF(COUNTIF('Verification Actions'!B2:B343,"* "&B32&" *")=0,"",IF(COUNTIFS('Verification Actions'!B2:B343,"* "&B32&" *",'Verification Actions'!E2:E343,"Verified")=COUNTIF('Verification Actions'!B2:B343,"* "&B32&" *"),"Compliant",IF(COUNTIFS('Verification Actions'!B2:B343,"* "&B32&" *",'Verification Actions'!E2:E343,"Verified")>0,"Partially Compliant","Not Compliant")))
A33: 32 | B33: AnnV_par1_1 | C33: Annex V | E33: Annex V, point 1 | F33: contain name and type and any additional information enabling the unique identification of the product with digital elements | I33: =IF(COUNTIF('Verification Actions'!B2:B343,"* "&B33&" *")=0,"",IF(COUNTIFS('Verification Actions'!B2:B343,"* "&B33&" *",'Verification Actions'!E2:E343,"Verified")=COUNTIF('Verification Actions'!B2:B343,"* "&B33&" *"),"Compliant",IF(COUNTIFS('Verification Actions'!B2:B343,"* "&B33&" *",'Verification Actions'!E2:E343,"Verified")>0,"Partially Compliant","Not Compliant")))
A34: 33 | B34: AnnV_par4_4 | C34: Annex V | E34: Annex V, point 4 | F34: contain object of the declaration (identification of the product with digital elements allowing traceability, which may include a photograph, where appropriate) | I34: =IF(COUNTIF('Verification Actions'!B2:B343,"* "&B34&" *")=0,"",IF(COUNTIFS('Verification Actions'!B2:B343,"* "&B34&" *",'Verification Actions'!E2:E343,"Verified")=COUNTIF('Verification Actions'!B2:B343,"* "&B34&" *"),"Compliant",IF(COUNTIFS('Verification Actions'!B2:B343,"* "&B34&" *",'Verification Actions'!E2:E343,"Verified")>0,"Partially Compliant","Not Compliant")))
A35: 34 | B35: AnnV_par5_5 | C35: Annex V | E35: Annex V, point 5 | F35: contain a statement that the object of the declaration described above is in conformity with the relevant Union harmonisation legislation | I35: =IF(COUNTIF('Verification Actions'!B2:B343,"* "&B35&" *")=0,"",IF(COUNTIFS('Verification Actions'!B2:B343,"* "&B35&" *",'Verification Actions'!E2:E343,"Verified")=COUNTIF('Verification Actions'!B2:B343,"* "&B35&" *"),"Compliant",IF(COUNTIFS('Verification Actions'!B2:B343,"* "&B35&" *",'Verification Actions'!E2:E343,"Verified")>0,"Partially Compliant","Not Compliant")))
A36: 35 | B36: AnnVI_par1_2 | C36: Annex VI | E36: Annex VI, point 1 | F36: State name and designation of the product with digital elements | I36: =IF(COUNTIF('Verification Actions'!B2:B343,"* "&B36&" *")=0,"",IF(COUNTIFS('Verification Actions'!B2:B343,"* "&B36&" *",'Verification Actions'!E2:E343,"Verified")=COUNTIF('Verification Actions'!B2:B343,"* "&B36&" *"),"Compliant",IF(COUNTIFS('Verification Actions'!B2:B343,"* "&B36&" *",'Verification Actions'!E2:E343,"Verified")>0,"Partially Compliant","Not Compliant")))
A37: 36 | B37: AnnVI_par1_3 | C37: Annex VI | E37: Annex VI, point 1 | F37: Declare that the product with digital elements is in compliance with Regulation (EU) 2024/2847 | I37: =IF(COUNTIF('Verification Actions'!B2:B343,"* "&B37&" *")=0,"",IF(COUNTIFS('Verification Actions'!B2:B343,"* "&B37&" *",'Verification Actions'!E2:E343,"Verified")=COUNTIF('Verification Actions'!B2:B343,"* "&B37&" *"),"Compliant",IF(COUNTIFS('Verification Actions'!B2:B343,"* "&B37&" *",'Verification Actions'!E2:E343,"Verified")>0,"Partially Compliant","Not Compliant")))
A38: 37 | B38: AnnVI_par1_1 | C38: Annex VI | E38: Annex VI, point 1 | F38: Provide the simplified EU declaration of conformity | I38: =IF(COUNTIF('Verification Actions'!B2:B343,"* "&B38&" *")=0,"",IF(COUNTIFS('Verification Actions'!B2:B343,"* "&B38&" *",'Verification Actions'!E2:E343,"Verified")=COUNTIF('Verification Actions'!B2:B343,"* "&B38&" *"),"Compliant",IF(COUNTIFS('Verification Actions'!B2:B343,"* "&B38&" *",'Verification Actions'!E2:E343,"Verified")>0,"Partially Compliant","Not Compliant")))
A39: 38 | B39: AnnVI_par1_4 | C39: Annex VI | E39: Annex VI, point 1 | F39: Provide the full text of the EU declaration of conformity at a specified internet address | I39: =IF(COUNTIF('Verification Actions'!B2:B343,"* "&B39&" *")=0,"",IF(COUNTIFS('Verification Actions'!B2:B343,"* "&B39&" *",'Verification Actions'!E2:E343,"Verified")=COUNTIF('Verification Actions'!B2:B343,"* "&B39&" *"),"Compliant",IF(COUNTIFS('Verification Actions'!B2:B343,"* "&B39&" *",'Verification Actions'!E2:E343,"Verified")>0,"Partially Compliant","Not Compliant")))
A40: 39 | B40: AnnVII_par1_1 | C40: Annex VII | E40: Annex VII, point 1 | F40: include a general description of the product with digital elements | I40: =IF(COUNTIF('Verification Actions'!B2:B343,"* "&B40&" *")=0,"",IF(COUNTIFS('Verification Actions'!B2:B343,"* "&B40&" *",'Verification Actions'!E2:E343,"Verified")=COUNTIF('Verification Actions'!B2:B343,"* "&B40&" *"),"Compliant",IF(COUNTIFS('Verification Actions'!B2:B343,"* "&B40&" *",'Verification Actions'!E2:E343,"Verified")>0,"Partially Compliant","Not Compliant")))
...

Sheet Verification Actions
A1: # | B1: Associated Obligations | C1: Verification Type | D1: Verification Description | E1: Status | F1: Required Evidence | G1: Evidence Provided | H1: Notes
A2: 1 | B2: ch2_sec1_art14_par4_3 | C2: Inspection | D2: Verify all required sections and content are present in the final report. | F2: Signed final report checklist or audit trail of report content review.
A3: 2 | B3: ch3_sec1_art31_par1_1 ch1_sec1_art6_par1_2 | C3: Inspection | D3: Inspect implementation of security controls documented in Annex I, Part II. | F3: System configuration files and implementation logs.
A4: 3 | B4: AnnVI_par1_1 | C4: Inspection | D4: Inspect the process for creating and approving the EU declaration of conformity. | F4: Record of internal approval for the EU declaration of conformity.
A5: 4 | B5: AnnI_PartII_par2_16 | C5: Inspection | D5: Inspection of records showing security updates and their deployment dates. | F5: Security Update Deployment Logs and Release Notes.
A6: 5 | B6: ch3_sec1_art28_par2_3 | C6: Inspection | D6: Inspect provided documentation for all required information related to product conformity. | F6: Checklist of mandatory documentation elements and confirmation of their presence.
A7: 6 | B7: AnnI_par2_12 | C7: Inspection | D7: Inspection of source code for implementation of mitigation techniques. | F7: Code review logs confirming integration of exploitation mitigation features.
A8: 7 | B8: AnnI_par2_9 | C8: Inspection | D8: Inspect implemented resilience and mitigation measures for essential functions. | F8: Configuration files and system logs demonstrating active resilience measures.
A9: 8 | B9: ch2_sec1_art13_par14_1 | C9: Inspection | D9: Inspection of records for product updates and conformity checks in production. | F9: Production logs demonstrating tracking of updates and conformity verification for product series.
A10: 9 | B10: ch3_sec1_art28_par1_2 | C10: Inspection | D10: Inspection of product/system evidence confirming compliance with Annex I requirements. | F10: Inspection report detailing findings related to Annex I compliance.
A11: 10 | B11: ch2_sec1_art13_par2_1 | C11: Inspection | D11: Inspect design documents for evidence of risk mitigation integration. | F11: Design specifications and architecture documents referencing risk analysis.
A12: 11 | B12: ch8_sec1_art69_par3_1 | C12: Inspection | D12: Verify existence of a vulnerability disclosure policy for pre-December 2027 products. | F12: Published vulnerability disclosure policy document.
A13: 12 | B13: ch3_sec1_art30_par4_1 | C13: Inspection | D13: Visually inspect the product or its packaging for the presence of the notified body identification number. | F13: Photographic evidence of the product/packaging with the identification number clearly visible.
... A343: 342 | B343: ch3_sec1_art32_par1_2 | C343: Waiver | D343: Waiver if alternative compliance demonstration method is approved by competent authority. | F343: Official waiver document
